[2025-01-26 21:43:52,025: INFO: main: Stage: Data Ingestion Stage started:]
[2025-01-26 21:43:52,025: INFO: common: yaml file: config\config.yaml loaded successfully:]
[2025-01-26 21:43:52,067: INFO: common: yaml file: params.yaml loaded successfully:]
[2025-01-26 21:43:52,067: INFO: common: Created directory at artifacts:]
[2025-01-26 21:43:52,067: INFO: common: Created directory at artifacts/data_ingestion:]
[2025-01-26 21:43:52,067: ERROR: main: "'ConfigBox' object has no attribute 'source_url'":]
Traceback (most recent call last):
  File "box\box.py", line 503, in box.box.Box.__getitem__
KeyError: 'source_url'

The above exception was the direct cause of the following exception:

Traceback (most recent call last):
  File "box\box.py", line 536, in box.box.Box.__getattr__
  File "box\box.py", line 524, in box.box.Box.__getitem__
box.exceptions.BoxKeyError: "'source_url'"

During handling of the above exception, another exception occurred:

Traceback (most recent call last):
  File "box\box.py", line 538, in box.box.Box.__getattr__
AttributeError: 'ConfigBox' object has no attribute 'source_url'

The above exception was the direct cause of the following exception:

Traceback (most recent call last):
  File "box\config_box.py", line 28, in box.config_box.ConfigBox.__getattr__
  File "box\box.py", line 552, in box.box.Box.__getattr__
box.exceptions.BoxKeyError: "'ConfigBox' object has no attribute 'source_url'"

During handling of the above exception, another exception occurred:

Traceback (most recent call last):
  File "box\box.py", line 503, in box.box.Box.__getitem__
KeyError: 'source_url'

The above exception was the direct cause of the following exception:

Traceback (most recent call last):
  File "box\box.py", line 536, in box.box.Box.__getattr__
  File "box\box.py", line 524, in box.box.Box.__getitem__
box.exceptions.BoxKeyError: "'source_url'"

During handling of the above exception, another exception occurred:

Traceback (most recent call last):
  File "box\box.py", line 538, in box.box.Box.__getattr__
AttributeError: 'ConfigBox' object has no attribute 'source_url'

The above exception was the direct cause of the following exception:

Traceback (most recent call last):
  File "E:\TextSummarizer\TextSummarizer\main.py", line 9, in <module>
    data_ingestion_pipeline.initiate_data_ingestion()
  File "E:\TextSummarizer\TextSummarizer\src\TextSummarizer\pipeline\data_ingestion_pipeline.py", line 11, in initiate_data_ingestion
    data_ingestion_config=config.get_data_ingestion_config()
  File "E:\TextSummarizer\TextSummarizer\src\TextSummarizer\config\configuration.py", line 17, in get_data_ingestion_config
    source_url=config.source_url,
  File "box\config_box.py", line 30, in box.config_box.ConfigBox.__getattr__
  File "box\box.py", line 552, in box.box.Box.__getattr__
box.exceptions.BoxKeyError: "'ConfigBox' object has no attribute 'source_url'"
[2025-01-26 21:45:45,795: INFO: main: Stage: Data Ingestion Stage started:]
[2025-01-26 21:45:45,795: INFO: common: yaml file: config\config.yaml loaded successfully:]
[2025-01-26 21:45:45,803: INFO: common: yaml file: params.yaml loaded successfully:]
[2025-01-26 21:45:45,803: INFO: common: Created directory at artifacts:]
[2025-01-26 21:45:45,806: INFO: common: Created directory at artifacts/data_ingestion:]
[2025-01-26 21:45:49,147: INFO: data_ingestion: Dataset Downloaded:]
[2025-01-26 21:45:49,608: INFO: main: Stage Data Ingestion Stage completed:]
[2025-01-26 23:47:36,579: INFO: config: PyTorch version 2.5.1 available.:]
[2025-01-26 23:47:42,084: INFO: main: Stage: Data Ingestion Stage started:]
[2025-01-26 23:47:42,106: INFO: common: yaml file: config\config.yaml loaded successfully:]
[2025-01-26 23:47:42,173: INFO: common: yaml file: params.yaml loaded successfully:]
[2025-01-26 23:47:42,180: INFO: common: Created directory at artifacts:]
[2025-01-26 23:47:42,180: INFO: common: Created directory at artifacts/data_ingestion:]
[2025-01-26 23:47:42,182: INFO: data_ingestion: File already exist:]
[2025-01-26 23:47:42,675: INFO: main: Stage Data Ingestion Stage completed:]
[2025-01-26 23:47:42,675: INFO: main: Stage: Data Transformation Stage started:]
[2025-01-26 23:47:42,675: INFO: common: yaml file: config\config.yaml loaded successfully:]
[2025-01-26 23:47:42,675: INFO: common: yaml file: params.yaml loaded successfully:]
[2025-01-26 23:47:42,682: INFO: common: Created directory at artifacts:]
[2025-01-26 23:47:42,683: ERROR: main: "'ConfigBox' object has no attribute 'root_dir'":]
Traceback (most recent call last):
  File "box\box.py", line 503, in box.box.Box.__getitem__
KeyError: 'root_dir'

The above exception was the direct cause of the following exception:

Traceback (most recent call last):
  File "box\box.py", line 536, in box.box.Box.__getattr__
  File "box\box.py", line 524, in box.box.Box.__getitem__
box.exceptions.BoxKeyError: "'root_dir'"

During handling of the above exception, another exception occurred:

Traceback (most recent call last):
  File "box\box.py", line 538, in box.box.Box.__getattr__
AttributeError: 'ConfigBox' object has no attribute 'root_dir'

The above exception was the direct cause of the following exception:

Traceback (most recent call last):
  File "box\config_box.py", line 28, in box.config_box.ConfigBox.__getattr__
  File "box\box.py", line 552, in box.box.Box.__getattr__
box.exceptions.BoxKeyError: "'ConfigBox' object has no attribute 'root_dir'"

During handling of the above exception, another exception occurred:

Traceback (most recent call last):
  File "box\box.py", line 503, in box.box.Box.__getitem__
KeyError: 'root_dir'

The above exception was the direct cause of the following exception:

Traceback (most recent call last):
  File "box\box.py", line 536, in box.box.Box.__getattr__
  File "box\box.py", line 524, in box.box.Box.__getitem__
box.exceptions.BoxKeyError: "'root_dir'"

During handling of the above exception, another exception occurred:

Traceback (most recent call last):
  File "box\box.py", line 538, in box.box.Box.__getattr__
AttributeError: 'ConfigBox' object has no attribute 'root_dir'

The above exception was the direct cause of the following exception:

Traceback (most recent call last):
  File "E:\TextSummarizer\TextSummarizer\main.py", line 21, in <module>
    data_transformation_pipeline.initiate_data_transformation()
  File "E:\TextSummarizer\TextSummarizer\src\TextSummarizer\pipeline\data_transformation_pipeline.py", line 11, in initiate_data_transformation
    data_transformation_config=config.get_data_transformation_config()
  File "E:\TextSummarizer\TextSummarizer\src\TextSummarizer\config\configuration.py", line 25, in get_data_transformation_config
    config=self.config.root_dir
  File "box\config_box.py", line 30, in box.config_box.ConfigBox.__getattr__
  File "box\box.py", line 552, in box.box.Box.__getattr__
box.exceptions.BoxKeyError: "'ConfigBox' object has no attribute 'root_dir'"
[2025-01-26 23:49:12,263: INFO: config: PyTorch version 2.5.1 available.:]
[2025-01-26 23:49:13,572: INFO: main: Stage: Data Ingestion Stage started:]
[2025-01-26 23:49:13,580: INFO: common: yaml file: config\config.yaml loaded successfully:]
[2025-01-26 23:49:13,585: INFO: common: yaml file: params.yaml loaded successfully:]
[2025-01-26 23:49:13,587: INFO: common: Created directory at artifacts:]
[2025-01-26 23:49:13,588: INFO: common: Created directory at artifacts/data_ingestion:]
[2025-01-26 23:49:13,590: INFO: data_ingestion: File already exist:]
[2025-01-26 23:49:13,812: INFO: main: Stage Data Ingestion Stage completed:]
[2025-01-26 23:49:13,812: INFO: main: Stage: Data Transformation Stage started:]
[2025-01-26 23:49:13,812: INFO: common: yaml file: config\config.yaml loaded successfully:]
[2025-01-26 23:49:13,819: INFO: common: yaml file: params.yaml loaded successfully:]
[2025-01-26 23:49:13,823: INFO: common: Created directory at artifacts:]
[2025-01-26 23:49:13,824: ERROR: main: "'ConfigBox' object has no attribute 'root_dir'":]
Traceback (most recent call last):
  File "box\box.py", line 503, in box.box.Box.__getitem__
KeyError: 'root_dir'

The above exception was the direct cause of the following exception:

Traceback (most recent call last):
  File "box\box.py", line 536, in box.box.Box.__getattr__
  File "box\box.py", line 524, in box.box.Box.__getitem__
box.exceptions.BoxKeyError: "'root_dir'"

During handling of the above exception, another exception occurred:

Traceback (most recent call last):
  File "box\box.py", line 538, in box.box.Box.__getattr__
AttributeError: 'ConfigBox' object has no attribute 'root_dir'

The above exception was the direct cause of the following exception:

Traceback (most recent call last):
  File "box\config_box.py", line 28, in box.config_box.ConfigBox.__getattr__
  File "box\box.py", line 552, in box.box.Box.__getattr__
box.exceptions.BoxKeyError: "'ConfigBox' object has no attribute 'root_dir'"

During handling of the above exception, another exception occurred:

Traceback (most recent call last):
  File "box\box.py", line 503, in box.box.Box.__getitem__
KeyError: 'root_dir'

The above exception was the direct cause of the following exception:

Traceback (most recent call last):
  File "box\box.py", line 536, in box.box.Box.__getattr__
  File "box\box.py", line 524, in box.box.Box.__getitem__
box.exceptions.BoxKeyError: "'root_dir'"

During handling of the above exception, another exception occurred:

Traceback (most recent call last):
  File "box\box.py", line 538, in box.box.Box.__getattr__
AttributeError: 'ConfigBox' object has no attribute 'root_dir'

The above exception was the direct cause of the following exception:

Traceback (most recent call last):
  File "E:\TextSummarizer\TextSummarizer\main.py", line 21, in <module>
    data_transformation_pipeline.initiate_data_transformation()
  File "E:\TextSummarizer\TextSummarizer\src\TextSummarizer\pipeline\data_transformation_pipeline.py", line 11, in initiate_data_transformation
    data_transformation_config=config.get_data_transformation_config()
  File "E:\TextSummarizer\TextSummarizer\src\TextSummarizer\config\configuration.py", line 25, in get_data_transformation_config
    config=self.config.root_dir
  File "box\config_box.py", line 30, in box.config_box.ConfigBox.__getattr__
  File "box\box.py", line 552, in box.box.Box.__getattr__
box.exceptions.BoxKeyError: "'ConfigBox' object has no attribute 'root_dir'"
[2025-01-26 23:51:25,354: INFO: config: PyTorch version 2.5.1 available.:]
[2025-01-26 23:51:25,830: INFO: main: Stage: Data Ingestion Stage started:]
[2025-01-26 23:51:25,838: INFO: common: yaml file: config\config.yaml loaded successfully:]
[2025-01-26 23:51:25,838: INFO: common: yaml file: params.yaml loaded successfully:]
[2025-01-26 23:51:25,838: INFO: common: Created directory at artifacts:]
[2025-01-26 23:51:25,844: INFO: common: Created directory at artifacts/data_ingestion:]
[2025-01-26 23:51:25,845: INFO: data_ingestion: File already exist:]
[2025-01-26 23:51:26,032: INFO: main: Stage Data Ingestion Stage completed:]
[2025-01-26 23:51:26,032: INFO: main: Stage: Data Transformation Stage started:]
[2025-01-26 23:51:26,040: INFO: common: yaml file: config\config.yaml loaded successfully:]
[2025-01-26 23:51:26,040: INFO: common: yaml file: params.yaml loaded successfully:]
[2025-01-26 23:51:26,040: INFO: common: Created directory at artifacts:]
[2025-01-26 23:51:26,045: INFO: common: Created directory at artifacts/data_transformation:]
[2025-01-26 23:51:47,532: INFO: main: Stage Data Transformation Stage completed:]
